Workbook

Sheet Line Data
A1: Towe rId | B1: 1 | C1: 2 | D1: 3 | E1: 4 | F1: 5 | G1: 6 | H1: 7 | I1: 8 | J1: 9 | K1: 10 | L1: 11 | M1: 12 | N1: 13 | O1: 14 | P1: 15 | Q1: 16 | R1: 17 | S1: 18 | T1: 19 | U1: 20 | V1: 21 | W1: 22 | X1: 23 | Y1: 24 | Z1: 25 | AA1: 26 | AB1: 27 | AC1: 28 | AD1: 29 | AE1: 30 | AF1: 31 | AG1: 32 | AH1: 33 | AI1: 34 | AJ1: 35 | AK1: 36 | AL1: 37 | AM1: 38 | AN1: 39 | AO1: 40 | AP1: 41 | AQ1: 42 | AR1: 43 | AS1: 44 | AT1: 45 | AU1: 46 | AV1: 47 | AW1: 48 | AX1: 49 | AY1: 50 | AZ1: 51 | BA1: 52 | BB1: 53 | BC1: 54 | BD1: 55 | BE1: 56 | BF1: 57 | BG1: 58 | BH1: 59 | BI1: 60 | BJ1: 61 | BK1: 62 | BL1: 63 | BM1: 64 | BN1: 65 | BO1: 66 | BP1: 67 | BQ1: 68 | BR1: 69 | BS1: 70 | BT1: 71 | BU1: 72 | BV1: 73 | BW1: 74 | BX1: 75 | BY1: 76 | BZ1: 77 | CA1: 78 | CB1: 79 | CC1: 80 | CD1: 81 | CE1: 82 | CF1: 83 | CG1: 84 | CH1: 85 | CI1: 86 | CJ1: 87 | CK1: 88 | CL1: 89 | CM1: 90 | CN1: 91 | CO1: 92 | CP1: 93 | CQ1: 94 | CR1: 95 | CS1: 96 | CT1: 97 | CU1: 98 | CV1: 99 | CW1: 100 | CX1: 101 | CY1: 102 | CZ1: 103 | DA1: 104 | DB1: 105 | DC1: 106 | DD1: 107 | DE1: 108 | DF1: 109 | DG1: 110 | DH1: 111 | DI1: 112 | DJ1: 113 | DK1: 114 | DL1: 115 | DM1: 116 | DN1: 117 | DO1: 118 | DP1: 119 | DQ1: 120 | DR1: 121 | DS1: 122 | DT1: 123 | DU1: 124 | DV1: 125 | DW1: 126 | DX1: 127 | DY1: 128 | DZ1: 129 | EA1: 130 | EB1: 131 | EC1: 132 | ED1: 133 | EE1: 134 | EF1: 135 | EG1: 136 | EH1: 137 | EI1: 138 | EJ1: 139 | EK1: 140 | EL1: 141 | EM1: 142 | EN1: 143 | EO1: 144 | EP1: 145 | EQ1: 146 | ER1: 147 | ES1: 148 | ET1: 149 | EU1: 150 | EV1: 151 | EW1: 152 | EX1: 153 | EY1: 154 | EZ1: 155 | FA1: 156 | FB1: 157 | FC1: 158 | FD1: 159 | FE1: 160 | FF1: 161 | FG1: 162 | FH1: 163 | FI1: 164 | FJ1: 165 | FK1: 166 | FL1: 167 | FM1: 168 | FN1: 169 | FO1: 170 | FP1: 171 | FQ1: 172 | FR1: 173 | FS1: 174 | FT1: 175 | FU1: 176 | FV1: 177 | FW1: 178 | FX1: 179 | FY1: 180
A2: x (km) | B2: 0.546 | C2: 1.092 | D2: 1.638 | E2: 2.184 | F2: 2.73 | G2: 3.276 | H2: 3.822 | I2: 4.368 | J2: 4.914 | K2: 5.46 | L2: 6.006 | M2: 6.552 | N2: 7.098 | O2: 7.644 | P2: 8.19 | Q2: 8.736 | R2: 9.282 | S2: 9.828 | T2: 10.374 | U2: 10.92 | V2: 11.466 | W2: 12.012 | X2: 12.558 | Y2: 13.104 | Z2: 13.65 | AA2: 14.196 | AB2: 14.742 | AC2: 15.288 | AD2: 15.834 | AE2: 16.38 | AF2: 16.776667 | AG2: 17.173333 | AH2: 17.57 | AI2: 17.966667 | AJ2: 18.363333 | AK2: 18.76 | AL2: 19.156667 | AM2: 19.553333 | AN2: 19.95 | AO2: 20.346667 | AP2: 20.743333 | AQ2: 21.14 | AR2: 21.536667 | AS2: 21.933333 | AT2: 22.33 | AU2: 22.726667 | AV2: 23.123333 | AW2: 23.52 | AX2: 24.01875 | AY2: 24.5175 | AZ2: 25.01625 | BA2: 25.515 | BB2: 26.01375 | BC2: 26.5125 | BD2: 27.01125 | BE2: 27.51 | BF2: 28.00875 | BG2: 28.5075 | BH2: 29.00625 | BI2: 29.505 | BJ2: 30.00375 | BK2: 30.5025 | BL2: 31.00125 | BM2: 31.5 | BN2: 31.939091 | BO2: 32.378182 | BP2: 32.817273 | BQ2: 33.256364 | BR2: 33.695455 | BS2: 34.134545 | BT2: 34.573636 | BU2: 35.012727 | BV2: 35.451818 | BW2: 35.890909 | BX2: 36.33 | BY2: 36.769091 | BZ2: 37.208182 | CA2: 37.647273 | CB2: 38.086364 | CC2: 38.525455 | CD2: 38.964545 | CE2: 39.403636 | CF2: 39.842727 | CG2: 40.281818 | CH2: 40.720909 | CI2: 41.16 | CJ2: 41.5625 | CK2: 41.965 | CL2: 42.3675 | CM2: 42.77 | CN2: 43.1725 | CO2: 43.575 | CP2: 43.9775 | CQ2: 44.38 | CR2: 44.7825 | CS2: 45.185 | CT2: 45.5875 | CU2: 45.99 | CV2: 46.3925 | CW2: 46.795 | CX2: 47.1975 | CY2: 47.6 | CZ2: 48.0025 | DA2: 48.405 | DB2: 48.8075 | DC2: 49.21 | DD2: 49.6125 | DE2: 50.015 | DF2: 50.4175 | DG2: 50.82 | DH2: 51.201818 | DI2: 51.583636 | DJ2: 51.965455 | DK2: 52.347273 | DL2: 52.729091 | DM2: 53.110909 | DN2: 53.492727 | DO2: 53.874545 | DP2: 54.256364 | DQ2: 54.638182 | DR2: 55.02 | DS2: 55.401818 | DT2: 55.783636 | DU2: 56.165455 | DV2: 56.547273 | DW2: 56.929091 | DX2: 57.310909 | DY2: 57.692727 | DZ2: 58.074545 | EA2: 58.456364 | EB2: 58.838182 | EC2: 59.22 | ED2: 59.78 | EE2: 60.34 | EF2: 60.9 | EG2: 61.46 | EH2: 62.02 | EI2: 62.58 | EJ2: 63.14 | EK2: 63.7 | EL2: 64.26 | EM2: 64.82 | EN2: 65.38 | EO2: 65.94 | EP2: 66.5 | EQ2: 67.06 | ER2: 67.62 | ES2: 68.18 | ET2: 68.74 | EU2: 69.3 | EV2: 69.836667 | EW2: 70.373333 | EX2: 70.91 | EY2: 71.446667 | EZ2: 71.983333 | FA2: 72.52 | FB2: 73.056667 | FC2: 73.593333 | FD2: 74.13 | FE2: 74.666667 | FF2: 75.203333 | FG2: 75.74 | FH2: 76.276667 | FI2: 76.813333 | FJ2: 77.35 | FK2: 77.886667 | FL2: 78.423333 | FM2: 78.96 | FN2: 79.496667 | FO2: 80.033333 | FP2: 80.57 | FQ2: 81.106667 | FR2: 81.643333 | FS2: 82.18 | FT2: 82.716667 | FU2: 83.253333 | FV2: 83.79 | FW2: 84.326667 | FX2: 84.863333 | FY2: 85
A3: y (km) | B3: 0 | C3: 0 | D3: 0 | E3: 0 | F3: 0 | G3: 0 | H3: 0 | I3: 0 | J3: 0 | K3: 0 | L3: 0 | M3: 0 | N3: 0 | O3: 0 | P3: 0 | Q3: 0 | R3: 0 | S3: 0 | T3: 0 | U3: 0 | V3: 0 | W3: 0 | X3: 0 | Y3: 0 | Z3: 0 | AA3: 0 | AB3: 0 | AC3: 0 | AD3: 0 | AE3: 0 | AF3: 0 | AG3: 0 | AH3: 0 | AI3: 0 | AJ3: 0 | AK3: 0 | AL3: 0 | AM3: 0 | AN3: 0 | AO3: 0 | AP3: 0 | AQ3: 0 | AR3: 0 | AS3: 0 | AT3: 0 | AU3: 0 | AV3: 0 | AW3: 0 | AX3: 0 | AY3: 0 | AZ3: 0 | BA3: 0 | BB3: 0 | BC3: 0 | BD3: 0 | BE3: 0 | BF3: 0 | BG3: 0 | BH3: 0 | BI3: 0 | BJ3: 0 | BK3: 0 | BL3: 0 | BM3: 0 | BN3: 0 | BO3: 0 | BP3: 0 | BQ3: 0 | BR3: 0 | BS3: 0 | BT3: 0 | BU3: 0 | BV3: 0 | BW3: 0 | BX3: 0 | BY3: 0 | BZ3: 0 | CA3: 0 | CB3: 0 | CC3: 0 | CD3: 0 | CE3: 0 | CF3: 0 | CG3: 0 | CH3: 0 | CI3: 0 | CJ3: 0 | CK3: 0 | CL3: 0 | CM3: 0 | CN3: 0 | CO3: 0 | CP3: 0 | CQ3: 0 | CR3: 0 | CS3: 0 | CT3: 0 | CU3: 0 | CV3: 0 | CW3: 0 | CX3: 0 | CY3: 0 | CZ3: 0 | DA3: 0 | DB3: 0 | DC3: 0 | DD3: 0 | DE3: 0 | DF3: 0 | DG3: 0 | DH3: 0 | DI3: 0 | DJ3: 0 | DK3: 0 | DL3: 0 | DM3: 0 | DN3: 0 | DO3: 0 | DP3: 0 | DQ3: 0 | DR3: 0 | DS3: 0 | DT3: 0 | DU3: 0 | DV3: 0 | DW3: 0 | DX3: 0 | DY3: 0 | DZ3: 0 | EA3: 0 | EB3: 0 | EC3: 0 | ED3: 0 | EE3: 0 | EF3: 0 | EG3: 0 | EH3: 0 | EI3: 0 | EJ3: 0 | EK3: 0 | EL3: 0 | EM3: 0 | EN3: 0 | EO3: 0 | EP3: 0 | EQ3: 0 | ER3: 0 | ES3: 0 | ET3: 0 | EU3: 0 | EV3: 0 | EW3: 0 | EX3: 0 | EY3: 0 | EZ3: 0 | FA3: 0 | FB3: 0 | FC3: 0 | FD3: 0 | FE3: 0 | FF3: 0 | FG3: 0 | FH3: 0 | FI3: 0 | FJ3: 0 | FK3: 0 | FL3: 0 | FM3: 0 | FN3: 0 | FO3: 0 | FP3: 0 | FQ3: 0 | FR3: 0 | FS3: 0 | FT3: 0 | FU3: 0 | FV3: 0 | FW3: 0 | FX3: 0 | FY3: 0
A4: z (km) | B4: 2.2144098 | C4: 2.1877843 | D4: 2.1613233 | E4: 2.135027 | F4: 2.1088953 | G4: 2.0829283 | H4: 2.0571258 | I4: 2.031488 | J4: 2.0060148 | K4: 1.9807062 | L4: 1.9555622 | M4: 1.9305828 | N4: 1.9057681 | O4: 1.881118 | P4: 1.8566325 | Q4: 1.8323116 | R4: 1.8081553 | S4: 1.7841637 | T4: 1.7603367 | U4: 1.7366743 | V4: 1.7131765 | W4: 1.6898434 | X4: 1.6666748 | Y4: 1.6436709 | Z4: 1.6208316 | AA4: 1.5981569 | AB4: 1.5756469 | AC4: 1.5533014 | AD4: 1.5311206 | AE4: 1.5091044 | AF4: 1.4932129 | AG4: 1.4774084 | AH4: 1.4616907 | AI4: 1.44606 | AJ4: 1.4305161 | AK4: 1.4150591 | AL4: 1.3996889 | AM4: 1.3844057 | AN4: 1.3692093 | AO4: 1.3540999 | AP4: 1.3390773 | AQ4: 1.3241416 | AR4: 1.3092928 | AS4: 1.2945309 | AT4: 1.2798558 | AU4: 1.2652677 | AV4: 1.2507664 | AW4: 1.236352 | AX4: 1.2183514 | AY4: 1.2004881 | AZ4: 1.1827621 | BA4: 1.1651735 | BB4: 1.1477223 | BC4: 1.1304085 | BD4: 1.113232 | BE4: 1.0961928 | BF4: 1.0792911 | BG4: 1.0625266 | BH4: 1.0458996 | BI4: 1.0294099 | BJ4: 1.0130576 | BK4: 0.99684259 | BL4: 0.98076498 | BM4: 0.96482473 | BN4: 0.9509049 | BO4: 0.93709154 | BP4: 0.92338464 | BQ4: 0.90978421 | BR4: 0.89629024 | BS4: 0.88290274 | BT4: 0.8696217 | BU4: 0.85644713 | BV4: 0.84337902 | BW4: 0.83041737 | BX4: 0.81756219 | BY4: 0.80481348 | BZ4: 0.79217123 | CA4: 0.77963544 | CB4: 0.76720612 | CC4: 0.75488326 | CD4: 0.74266687 | CE4: 0.73055694 | CF4: 0.71855348 | CG4: 0.70665648 | CH4: 0.69486595 | CI4: 0.68318188 | CJ4: 0.67256501 | CK4: 0.6620376 | CL4: 0.65159965 | CM4: 0.64125116 | CN4: 0.63099213 | CO4: 0.62082256 | CP4: 0.61074244 | CQ4: 0.60075179 | CR4: 0.5908506 | CS4: 0.58103887 | CT4: 0.5713166 | CU4: 0.56168379 | CV4: 0.55214043 | CW4: 0.54268654 | CX4: 0.53332211 | CY4: 0.52404714 | CZ4: 0.51486162 | DA4: 0.50576557 | DB4: 0.49675898 | DC4: 0.48784184 | DD4: 0.47901417 | DE4: 0.47027596 | DF4: 0.4616272 | DG4: 0.45306791 | DH4: 0.4450311 | DI4: 0.4370748 | DJ4: 0.429199 | DK4: 0.4214037 | DL4: 0.41368891 | DM4: 0.40605462 | DN4: 0.39850083 | DO4: 0.39102754 | DP4: 0.38363475 | DQ4: 0.37632247 | DR4: 0.36909069 | DS4: 0.36193941 | DT4: 0.35486864 | DU4: 0.34787837 | DV4: 0.3409686 | DW4: 0.33413933 | DX4: 0.32739056 | DY4: 0.3207223 | DZ4: 0.31413454 | EA4: 0.30762729 | EB4: 0.30120053 | EC4: 0.29485428 | ED4: 0.28569206 | EE4: 0.27670302 | EF4: 0.26788714 | EG4: 0.25924443 | EH4: 0.2507749 | EI4: 0.24247853 | EJ4: 0.23435534 | EK4: 0.22640531 | EL4: 0.21862845 | EM4: 0.21102477 | EN4: 0.20359425 | EO4: 0.1963369 | EP4: 0.18925273 | EQ4: 0.18234172 | ER4: 0.17560388 | ES4: 0.16903921 | ET4: 0.16264772 | EU4: 0.15642939 | EV4: 0.15063266 | EW4: 0.14499496 | EX4: 0.13951631 | EY4: 0.13419669 | EZ4: 0.12903612 | FA4: 0.12403459 | FB4: 0.11919209 | FC4: 0.11450864 | FD4: 0.10998422 | FE4: 0.10561884 | FF4: 0.10141251 | FG4: 0.097365212 | FH4: 0.093476956 | FI4: 0.089747739 | FJ4: 0.086177562 | FK4: 0.082766425 | FL4: 0.079514328 | FM4: 0.07642127 | FN4: 0.073487252 | FO4: 0.070712273 | FP4: 0.068096335 | FQ4: 0.065639436 | FR4: 0.063341577 | FS4: 0.061202758 | FT4: 0.059222978 | FU4: 0.057402238 | FV4: 0.055740538 | FW4: 0.054237878 | FX4: 0.052894257 | FY4: 0.0525775
A5: Ng (#/km2) | B5: 3.9612769 | C5: 4.3331635 | D5: 4.6955288 | E5: 5.0484421 | F5: 5.3919734 | G5: 5.7261929 | H5: 6.0511713 | I5: 6.3669799 | J5: 6.67369 | K5: 6.9713738 | L5: 7.2601037 | M5: 7.5399524 | N5: 7.8109933 | O5: 8.0733 | P5: 8.3269467 | Q5: 8.572008 | R5: 8.8085588 | S5: 9.0366744 | T5: 9.2564308 | U5: 9.4679042 | V5: 9.6711713 | W5: 9.8663091 | X5: 10.053395 | Y5: 10.232508 | Z5: 10.403725 | AA5: 10.567125 | AB5: 10.722789 | AC5: 10.870795 | AD5: 11.011223 | AE5: 11.144154 | AF5: 11.236072 | AG5: 11.324108 | AH5: 11.408292 | AI5: 11.488655 | AJ5: 11.56523 | AK5: 11.638047 | AL5: 11.70714 | AM5: 11.772539 | AN5: 11.834276 | AO5: 11.892384 | AP5: 11.946896 | AQ5: 11.997842 | AR5: 12.045257 | AS5: 12.089172 | AT5: 12.12962 | AU5: 12.166634 | AV5: 12.200247 | AW5: 12.230492 | AX5: 12.263793 | AY5: 12.291887 | AZ5: 12.314843 | BA5: 12.332726 | BB5: 12.345604 | BC5: 12.353544 | BD5: 12.356614 | BE5: 12.354883 | BF5: 12.348417 | BG5: 12.337287 | BH5: 12.321561 | BI5: 12.301308 | BJ5: 12.276598 | BK5: 12.2475 | BL5: 12.214085 | BM5: 12.176423 | BN5: 12.139807 | BO5: 12.100003 | BP5: 12.057059 | BQ5: 12.011024 | BR5: 11.961947 | BS5: 11.909877 | BT5: 11.854864 | BU5: 11.796956 | BV5: 11.736205 | BW5: 11.672659 | BX5: 11.606368 | BY5: 11.537384 | BZ5: 11.465755 | CA5: 11.391534 | CB5: 11.31477 | CC5: 11.235515 | CD5: 11.15382 | CE5: 11.069735 | CF5: 10.983313 | CG5: 10.894605 | CH5: 10.803663 | CI5: 10.710539 | CJ5: 10.623304 | CK5: 10.534318 | CL5: 10.443624 | CM5: 10.351262 | CN5: 10.257272 | CO5: 10.161696 | CP5: 10.064573 | CQ5: 9.9659462 | CR5: 9.8658557 | CS5: 9.7643431 | CT5: 9.6614498 | CU5: 9.5572175 | CV5: 9.4516879 | CW5: 9.3449027 | CX5: 9.2369041 | CY5: 9.127734 | CZ5: 9.0174347 | DA5: 8.9060486 | DB5: 8.7936181 | DC5: 8.6801858 | DD5: 8.5657944 | DE5: 8.4504869 | DF5: 8.3343061 | DG5: 8.2172953 | DH5: 8.1055688 | DI5: 7.9931713 | DJ5: 7.8801399 | DK5: 7.7665116 | DL5: 7.6523239 | DM5: 7.5376142 | DN5: 7.4224199 | DO5: 7.3067787 | DP5: 7.1907284 | DQ5: 7.0743067 | DR5: 6.9575516 | DS5: 6.8405011 | DT5: 6.7231933 | DU5: 6.6056665 | DV5: 6.487959 | DW5: 6.3701092 | DX5: 6.2521556 | DY5: 6.134137 | DZ5: 6.0160921 | EA5: 5.8980596 | EB5: 5.7800786 | EC5: 5.6621881 | ED5: 5.4895276 | EE5: 5.3172699 | EF5: 5.1455394 | EG5: 4.9744609 | EH5: 4.8041598 | EI5: 4.6347619 | EJ5: 4.4663935 | EK5: 4.2991813 | EL5: 4.1332526 | EM5: 3.9687349 | EN5: 3.8057566 | EO5: 3.6444462 | EP5: 3.4849328 | EQ5: 3.327346 | ER5: 3.1718158 | ES5: 3.0184729 | ET5: 2.8674481 | EU5: 2.718873 | EV5: 2.5789093 | EW5: 2.441433 | EX5: 2.3065612 | EY5: 2.174411 | EZ5: 2.0451003 | FA5: 1.9187472 | FB5: 1.7954702 | FC5: 1.6753882 | FD5: 1.5586205 | FE5: 1.4452869 | FF5: 1.3355074 | FG5: 1.2294026 | FH5: 1.1270934 | FI5: 1.0287011 | FJ5: 0.93434747 | FK5: 0.84415451 | FL5: 0.75824477 | FM5: 0.67674115 | FN5: 0.59976695 | FO5: 0.52744587 | FP5: 0.45990201 | FQ5: 0.39725986 | FR5: 0.33964431 | FS5: 0.28718066 | FT5: 0.23999459 | FU5: 0.1982122 | FV5: 0.16195997 | FW5: 0.13136477 | FX5: 0.1065539 | FY5: 0.101175
A6: TowerType | B6: 1 | C6: 1 | D6: 1 | E6: 1 | F6: 1 | G6: 1 | H6: 1 | I6: 1 | J6: 1 | K6: 1 | L6: 1 | M6: 1 | N6: 1 | O6: 1 | P6: 1 | Q6: 1 | R6: 1 | S6: 1 | T6: 1 | U6: 1 | V6: 1 | W6: 1 | X6: 1 | Y6: 1 | Z6: 1 | AA6: 1 | AB6: 1 | AC6: 1 | AD6: 1 | AE6: 1 | AF6: 2 | AG6: 2 | AH6: 2 | AI6: 2 | AJ6: 2 | AK6: 2 | AL6: 2 | AM6: 2 | AN6: 2 | AO6: 2 | AP6: 2 | AQ6: 2 | AR6: 2 | AS6: 2 | AT6: 2 | AU6: 2 | AV6: 2 | AW6: 2 | AX6: 3 | AY6: 3 | AZ6: 3 | BA6: 3 | BB6: 3 | BC6: 3 | BD6: 3 | BE6: 3 | BF6: 3 | BG6: 3 | BH6: 3 | BI6: 3 | BJ6: 3 | BK6: 3 | BL6: 3 | BM6: 3 | BN6: 4 | BO6: 4 | BP6: 4 | BQ6: 4 | BR6: 4 | BS6: 4 | BT6: 4 | BU6: 4 | BV6: 4 | BW6: 4 | BX6: 4 | BY6: 4 | BZ6: 4 | CA6: 4 | CB6: 4 | CC6: 4 | CD6: 4 | CE6: 4 | CF6: 4 | CG6: 4 | CH6: 4 | CI6: 4 | CJ6: 5 | CK6: 5 | CL6: 5 | CM6: 5 | CN6: 5 | CO6: 5 | CP6: 5 | CQ6: 5 | CR6: 5 | CS6: 5 | CT6: 5 | CU6: 5 | CV6: 5 | CW6: 5 | CX6: 5 | CY6: 5 | CZ6: 5 | DA6: 5 | DB6: 5 | DC6: 5 | DD6: 5 | DE6: 5 | DF6: 5 | DG6: 5 | DH6: 1 | DI6: 1 | DJ6: 1 | DK6: 1 | DL6: 1 | DM6: 1 | DN6: 1 | DO6: 1 | DP6: 1 | DQ6: 1 | DR6: 1 | DS6: 1 | DT6: 1 | DU6: 1 | DV6: 1 | DW6: 1 | DX6: 1 | DY6: 1 | DZ6: 1 | EA6: 1 | EB6: 1 | EC6: 1 | ED6: 2 | EE6: 2 | EF6: 2 | EG6: 2 | EH6: 2 | EI6: 2 | EJ6: 2 | EK6: 2 | EL6: 2 | EM6: 2 | EN6: 2 | EO6: 2 | EP6: 2 | EQ6: 2 | ER6: 2 | ES6: 2 | ET6: 2 | EU6: 2 | EV6: 3 | EW6: 3 | EX6: 3 | EY6: 3 | EZ6: 3 | FA6: 3 | FB6: 3 | FC6: 3 | FD6: 3 | FE6: 3 | FF6: 3 | FG6: 3 | FH6: 3 | FI6: 3 | FJ6: 3 | FK6: 3 | FL6: 3 | FM6: 3 | FN6: 3 | FO6: 3 | FP6: 3 | FQ6: 3 | FR6: 3 | FS6: 3 | FT6: 3 | FU6: 3 | FV6: 3 | FW6: 3 | FX6: 3 | FY6: 3
A7: rvd (ohm-m) | B7: 3951.88 | C7: 3671.231 | D7: 3408.3995 | E7: 3162.8388 | F7: 2934.0096 | G7: 2721.3795 | H7: 2524.423 | I7: 2342.6217 | J7: 2175.4645 | K7: 2022.447 | L7: 1883.072 | M7: 1756.8492 | N7: 1643.2956 | O7: 1541.935 | P7: 1452.2984 | Q7: 1373.9236 | R7: 1306.3558 | S7: 1249.1469 | T7: 1201.856 | U7: 1164.0493 | V7: 1135.2998 | W7: 1115.1879 | X7: 1103.3006 | Y7: 1099.2324 | Z7: 1102.5844 | AA7: 1112.9651 | AB7: 1129.9899 | AC7: 1153.2811 | AD7: 1182.4682 | AE7: 1217.1878 | AF7: 1245.6776 | AG7: 1276.7648 | AH7: 1310.317 | AI7: 1346.2037 | AJ7: 1384.2964 | AK7: 1424.4688 | AL7: 1466.5962 | AM7: 1510.556 | AN7: 1556.2276 | AO7: 1603.4923 | AP7: 1652.2335 | AQ7: 1702.3365 | AR7: 1753.6883 | AS7: 1806.1782 | AT7: 1859.6974 | AU7: 1914.1389 | AV7: 1969.3978 | AW7: 2025.3711 | AX7: 2096.6077 | AY7: 2168.6178 | AZ7: 2241.2099 | BA7: 2314.1974 | BB7: 2387.3986 | BC7: 2460.6367 | BD7: 2533.7397 | BE7: 2606.5408 | BF7: 2678.8778 | BG7: 2750.5934 | BH7: 2821.5355 | BI7: 2891.5566 | BJ7: 2960.5142 | BK7: 3028.2707 | BL7: 3094.6934 | BM7: 3159.6546 | BN7: 3215.5377 | BO7: 3270.1119 | BP7: 3323.2996 | BQ7: 3375.0257 | BR7: 3425.2186 | BS7: 3473.8092 | BT7: 3520.7315 | BU7: 3565.9225 | BV7: 3609.322 | BW7: 3650.873 | BX7: 3690.5212 | BY7: 3728.2154 | BZ7: 3763.9071 | CA7: 3797.551 | CB7: 3829.1048 | CC7: 3858.5288 | CD7: 3885.7865 | CE7: 3910.8444 | CF7: 3933.6717 | CG7: 3954.2407 | CH7: 3972.5267 | CI7: 3988.5079 | CJ7: 4001.1163 | CK7: 4011.7597 | CL7: 4020.4278 | CM7: 4027.1124 | CN7: 4031.8073 | CO7: 4034.5084 | CP7: 4035.2139 | CQ7: 4033.9237 | CR7: 4030.6401 | CS7: 4025.3673 | CT7: 4018.1117 | CU7: 4008.8816 | CV7: 3997.6875 | CW7: 3984.5421 | CX7: 3969.4599 | CY7: 3952.4577 | CZ7: 3933.5544 | DA7: 3912.7707 | DB7: 3890.1296 | DC7: 3865.6562 | DD7: 3839.3776 | DE7: 3811.323 | DF7: 3781.5237 | DG7: 3750.013 | DH7: 3718.5718 | DI7: 3685.6545 | DJ7: 3651.2947 | DK7: 3615.5277 | DL7: 3578.3906 | DM7: 3539.922 | DN7: 3500.1624 | DO7: 3459.1539 | DP7: 3416.9401 | DQ7: 3373.5666 | DR7: 3329.0804 | DS7: 3283.5305 | DT7: 3236.9671 | DU7: 3189.4427 | DV7: 3141.0109 | DW7: 3091.7274 | DX7: 3041.6493 | DY7: 2990.8356 | DZ7: 2939.3469 | EA7: 2887.2455 | EB7: 2834.5952 | EC7: 2781.4618 | ED7: 2702.8 | EE7: 2623.463 | EF7: 2543.6775 | EG7: 2463.6781 | EH7: 2383.7072 | EI7: 2304.0148 | EJ7: 2224.8588 | EK7: 2146.5049 | EL7: 2069.2267 | EM7: 1993.3053 | EN7: 1919.0299 | EO7: 1846.6973 | EP7: 1776.6121 | EQ7: 1709.0867 | ER7: 1644.4414 | ES7: 1583.0041 | ET7: 1525.1107 | EU7: 1471.1047 | EV7: 1423.3219 | EW7: 1379.7479 | EX7: 1340.7053 | EY7: 1306.5232 | EZ7: 1277.5373 | FA7: 1254.0898 | FB7: 1236.5294 | FC7: 1225.2117 | FD7: 1220.4986 | FE7: 1222.7585 | FF7: 1232.3666 | FG7: 1249.7045 | FH7: 1275.1605 | FI7: 1309.1294 | FJ7: 1352.0125 | FK7: 1404.2177 | FL7: 1466.1597 | FM7: 1538.2594 | FN7: 1620.9446 | FO7: 1714.6494 | FP7: 1819.8146 | FQ7: 1936.8877 | FR7: 2066.3224 | FS7: 2208.5793 | FT7: 2364.1256 | FU7: 2533.4347 | FV7: 2716.987 | FW7: 2915.2692 | FX7: 3128.7747 | FY7: 3185.6375
A8: altitude (m) | B8: 2214.4098 | C8: 2187.7843 | D8: 2161.3233 | E8: 2135.027 | F8: 2108.8953 | G8: 2082.9283 | H8: 2057.1258 | I8: 2031.488 | J8: 2006.0148 | K8: 1980.7062 | L8: 1955.5622 | M8: 1930.5828 | N8: 1905.7681 | O8: 1881.118 | P8: 1856.6325 | Q8: 1832.3116 | R8: 1808.1553 | S8: 1784.1637 | T8: 1760.3367 | U8: 1736.6743 | V8: 1713.1765 | W8: 1689.8434 | X8: 1666.6748 | Y8: 1643.6709 | Z8: 1620.8316 | AA8: 1598.1569 | AB8: 1575.6469 | AC8: 1553.3014 | AD8: 1531.1206 | AE8: 1509.1044 | AF8: 1493.2129 | AG8: 1477.4084 | AH8: 1461.6907 | AI8: 1446.06 | AJ8: 1430.5161 | AK8: 1415.0591 | AL8: 1399.6889 | AM8: 1384.4057 | AN8: 1369.2093 | AO8: 1354.0999 | AP8: 1339.0773 | AQ8: 1324.1416 | AR8: 1309.2928 | AS8: 1294.5309 | AT8: 1279.8558 | AU8: 1265.2677 | AV8: 1250.7664 | AW8: 1236.352 | AX8: 1218.3514 | AY8: 1200.4881 | AZ8: 1182.7621 | BA8: 1165.1735 | BB8: 1147.7223 | BC8: 1130.4085 | BD8: 1113.232 | BE8: 1096.1928 | BF8: 1079.2911 | BG8: 1062.5266 | BH8: 1045.8996 | BI8: 1029.4099 | BJ8: 1013.0576 | BK8: 996.84259 | BL8: 980.76498 | BM8: 964.82472 | BN8: 950.9049 | BO8: 937.09154 | BP8: 923.38464 | BQ8: 909.78421 | BR8: 896.29024 | BS8: 882.90274 | BT8: 869.6217 | BU8: 856.44713 | BV8: 843.37902 | BW8: 830.41737 | BX8: 817.56219 | BY8: 804.81348 | BZ8: 792.17123 | CA8: 779.63544 | CB8: 767.20612 | CC8: 754.88326 | CD8: 742.66687 | CE8: 730.55694 | CF8: 718.55348 | CG8: 706.65648 | CH8: 694.86595 | CI8: 683.18188 | CJ8: 672.56501 | CK8: 662.0376 | CL8: 651.59965 | CM8: 641.25116 | CN8: 630.99213 | CO8: 620.82256 | CP8: 610.74244 | CQ8: 600.75179 | CR8: 590.8506 | CS8: 581.03887 | CT8: 571.3166 | CU8: 561.68379 | CV8: 552.14043 | CW8: 542.68654 | CX8: 533.32211 | CY8: 524.04714 | CZ8: 514.86162 | DA8: 505.76557 | DB8: 496.75898 | DC8: 487.84184 | DD8: 479.01417 | DE8: 470.27596 | DF8: 461.6272 | DG8: 453.06791 | DH8: 445.0311 | DI8: 437.0748 | DJ8: 429.199 | DK8: 421.4037 | DL8: 413.68891 | DM8: 406.05462 | DN8: 398.50083 | DO8: 391.02754 | DP8: 383.63475 | DQ8: 376.32247 | DR8: 369.09069 | DS8: 361.93941 | DT8: 354.86864 | DU8: 347.87837 | DV8: 340.9686 | DW8: 334.13933 | DX8: 327.39056 | DY8: 320.7223 | DZ8: 314.13454 | EA8: 307.62729 | EB8: 301.20053 | EC8: 294.85428 | ED8: 285.69206 | EE8: 276.70302 | EF8: 267.88714 | EG8: 259.24443 | EH8: 250.7749 | EI8: 242.47853 | EJ8: 234.35534 | EK8: 226.40531 | EL8: 218.62845 | EM8: 211.02477 | EN8: 203.59425 | EO8: 196.3369 | EP8: 189.25272 | EQ8: 182.34172 | ER8: 175.60388 | ES8: 169.03921 | ET8: 162.64772 | EU8: 156.42939 | EV8: 150.63266 | EW8: 144.99496 | EX8: 139.51631 | EY8: 134.19669 | EZ8: 129.03612 | FA8: 124.03459 | FB8: 119.19209 | FC8: 114.50864 | FD8: 109.98422 | FE8: 105.61884 | FF8: 101.41251 | FG8: 97.365212 | FH8: 93.476956 | FI8: 89.747739 | FJ8: 86.177562 | FK8: 82.766425 | FL8: 79.514328 | FM8: 76.42127 | FN8: 73.487252 | FO8: 70.712273 | FP8: 68.096335 | FQ8: 65.639436 | FR8: 63.341577 | FS8: 61.202758 | FT8: 59.222978 | FU8: 57.402238 | FV8: 55.740538 | FW8: 54.237878 | FX8: 52.894257 | FY8: 52.5775
A9: Temperature (degC) | B9: 21.365159 | C9: 20.81633 | D9: 20.295839 | E9: 19.80302 | F9: 19.33721 | G9: 18.897754 | H9: 18.484005 | I9: 18.09532 | J9: 17.731063 | K9: 17.390606 | L9: 17.073325 | M9: 16.778604 | N9: 16.505833 | O9: 16.254409 | P9: 16.023733 | Q9: 15.813216 | R9: 15.622272 | S9: 15.450324 | T9: 15.2968 | U9: 15.161134 | V9: 15.042769 | W9: 14.941151 | X9: 14.855734 | Y9: 14.785979 | Z9: 14.731352 | AA9: 14.691327 | AB9: 14.665383 | AC9: 14.653006 | AD9: 14.653688 | AE9: 14.666929 | AF9: 14.684141 | AG9: 14.707533 | AH9: 14.736918 | AI9: 14.772112 | AJ9: 14.812933 | AK9: 14.8592 | AL9: 14.910735 | AM9: 14.967361 | AN9: 15.028903 | AO9: 15.095186 | AP9: 15.16604 | AQ9: 15.241296 | AR9: 15.320783 | AS9: 15.404338 | AT9: 15.491794 | AU9: 15.58299 | AV9: 15.677764 | AW9: 15.775958 | AX9: 15.904032 | AY9: 16.036955 | AZ9: 16.174422 | BA9: 16.316134 | BB9: 16.461794 | BC9: 16.611112 | BD9: 16.763802 | BE9: 16.919582 | BF9: 17.078173 | BG9: 17.239303 | BH9: 17.402704 | BI9: 17.56811 | BJ9: 17.735263 | BK9: 17.903906 | BL9: 18.07379 | BM9: 18.244668 | BN9: 18.395736 | BO9: 18.547224 | BP9: 18.698973 | BQ9: 18.850826 | BR9: 19.00263 | BS9: 19.154231 | BT9: 19.305482 | BU9: 19.456236 | BV9: 19.606351 | BW9: 19.755684 | BX9: 19.904098 | BY9: 20.051458 | BZ9: 20.19763 | CA9: 20.342485 | CB9: 20.485895 | CC9: 20.627735 | CD9: 20.767884 | CE9: 20.906222 | CF9: 21.042632 | CG9: 21.177 | CH9: 21.309215 | CI9: 21.439168 | CJ9: 21.556214 | CK9: 21.67119 | CL9: 21.78402 | CM9: 21.894626 | CN9: 22.002935 | CO9: 22.108875 | CP9: 22.212376 | CQ9: 22.313368 | CR9: 22.411787 | CS9: 22.507566 | CT9: 22.600644 | CU9: 22.69096 | CV9: 22.778454 | CW9: 22.863071 | CX9: 22.944754 | CY9: 23.02345 | CZ9: 23.099108 | DA9: 23.17168 | DB9: 23.241116 | DC9: 23.307372 | DD9: 23.370403 | DE9: 23.430168 | DF9: 23.486627 | DG9: 23.539742 | DH9: 23.587003 | DI9: 23.631193 | DJ9: 23.672284 | DK9: 23.710249 | DL9: 23.745064 | DM9: 23.776706 | DN9: 23.805152 | DO9: 23.830383 | DP9: 23.85238 | DQ9: 23.871125 | DR9: 23.886604 | DS9: 23.898803 | DT9: 23.907708 | DU9: 23.913309 | DV9: 23.915596 | DW9: 23.914561 | DX9: 23.910199 | DY9: 23.902504 | DZ9: 23.891472 | EA9: 23.877102 | EB9: 23.859395 | EC9: 23.83835 | ED9: 23.801454 | EE9: 23.757401 | EF9: 23.706213 | EG9: 23.647918 | EH9: 23.582552 | EI9: 23.510159 | EJ9: 23.430789 | EK9: 23.344499 | EL9: 23.251354 | EM9: 23.151423 | EN9: 23.044788 | EO9: 22.931531 | EP9: 22.811748 | EQ9: 22.685536 | ER9: 22.553003 | ES9: 22.414263 | ET9: 22.269437 | EU9: 22.118653 | EV9: 21.968685 | EW9: 21.813494 | EX9: 21.653212 | EY9: 21.487974 | EZ9: 21.317924 | FA9: 21.143212 | FB9: 20.963991 | FC9: 20.780423 | FD9: 20.592674 | FE9: 20.400918 | FF9: 20.205332 | FG9: 20.006103 | FH9: 19.80342 | FI9: 19.597481 | FJ9: 19.388487 | FK9: 19.176648 | FL9: 18.962178 | FM9: 18.745298 | FN9: 18.526235 | FO9: 18.30522 | FP9: 18.082493 | FQ9: 17.858297 | FR9: 17.632884 | FS9: 17.40651 | FT9: 17.179437 | FU9: 16.951934 | FV9: 16.724274 | FW9: 16.496739 | FX9: 16.269614 | FY9: 16.211875

Sheet TowerData
A1: TowType | B1: r4=r5(m) | C1: a45 (m) | D1: a14(m) | E1: a15(m) | F1: a45(m) | G1: b14(m) | H1: b15(m) | I1: b45(m) | J1: h4=h5 (m) | K1: Observations
A2: 1 | B2: 0.008435 | C2: 13.4 | D2: 89.7 | E2: 88.7 | F2: 108.23 | G2: 23 | H2: 18.7 | I2: 13.4 | J2: 53.7 | K2: A30
A3: 2 | B3: 0.008435 | C3: 9.75 | D3: 59.52 | E3: 58.72 | F3: 78.17 | G3: 21.21 | H3: 18.84 | I3: 9.75 | J3: 38.5 | K3: 3R/S
A4: 3 | B4: 0.008435 | C4: 16 | D4: 70.34 | E4: 68.5 | F4: 99.29 | G4: 33.55 | H4: 29.5 | I4: 16 | J4: 49 | K4: A1
A5: 4 | B5: 0.008435 | C5: 11.9 | D5: 81.27 | E5: 80.7 | F5: 112.1 | G5: 22.16 | H5: 18.7 | I5: 11.9 | J5: 50.1 | K5: A60
A6: 5 | B6: 0.008435 | C6: 16 | D6: 80.11 | E6: 78.5 | F6: 109.17 | G6: 33.55 | H6: 29.5 | I6: 16 | J6: 54 | K6: A2

Sheet CIik
A1: k/i | B1: Tower i
A2: Insulation cost k | B2: 1 | C2: 2 | D2: 3 | E2: 4 | F2: 5 | G2: 6 | H2: 7 | I2: 8 | J2: 9 | K2: 10 | L2: 11 | M2: 12 | N2: 13 | O2: 14 | P2: 15 | Q2: 16 | R2: 17 | S2: 18 | T2: 19 | U2: 20 | V2: 21 | W2: 22 | X2: 23 | Y2: 24 | Z2: 25 | AA2: 26 | AB2: 27 | AC2: 28 | AD2: 29 | AE2: 30 | AF2: 31 | AG2: 32 | AH2: 33 | AI2: 34 | AJ2: 35 | AK2: 36 | AL2: 37 | AM2: 38 | AN2: 39 | AO2: 40 | AP2: 41 | AQ2: 42 | AR2: 43 | AS2: 44 | AT2: 45 | AU2: 46 | AV2: 47 | AW2: 48 | AX2: 49 | AY2: 50 | AZ2: 51 | BA2: 52 | BB2: 53 | BC2: 54 | BD2: 55 | BE2: 56 | BF2: 57 | BG2: 58 | BH2: 59 | BI2: 60 | BJ2: 61 | BK2: 62 | BL2: 63 | BM2: 64 | BN2: 65 | BO2: 66 | BP2: 67 | BQ2: 68 | BR2: 69 | BS2: 70 | BT2: 71 | BU2: 72 | BV2: 73 | BW2: 74 | BX2: 75 | BY2: 76 | BZ2: 77 | CA2: 78 | CB2: 79 | CC2: 80 | CD2: 81 | CE2: 82 | CF2: 83 | CG2: 84 | CH2: 85 | CI2: 86 | CJ2: 87 | CK2: 88 | CL2: 89 | CM2: 90 | CN2: 91 | CO2: 92 | CP2: 93 | CQ2: 94 | CR2: 95 | CS2: 96 | CT2: 97 | CU2: 98 | CV2: 99 | CW2: 100 | CX2: 101 | CY2: 102 | CZ2: 103 | DA2: 104 | DB2: 105 | DC2: 106 | DD2: 107 | DE2: 108 | DF2: 109 | DG2: 110 | DH2: 111 | DI2: 112 | DJ2: 113 | DK2: 114 | DL2: 115 | DM2: 116 | DN2: 117 | DO2: 118 | DP2: 119 | DQ2: 120 | DR2: 121 | DS2: 122 | DT2: 123 | DU2: 124 | DV2: 125 | DW2: 126 | DX2: 127 | DY2: 128 | DZ2: 129 | EA2: 130 | EB2: 131 | EC2: 132 | ED2: 133 | EE2: 134 | EF2: 135 | EG2: 136 | EH2: 137 | EI2: 138 | EJ2: 139 | EK2: 140 | EL2: 141 | EM2: 142 | EN2: 143 | EO2: 144 | EP2: 145 | EQ2: 146 | ER2: 147 | ES2: 148 | ET2: 149 | EU2: 150 | EV2: 151 | EW2: 152 | EX2: 153 | EY2: 154 | EZ2: 155 | FA2: 156 | FB2: 157 | FC2: 158 | FD2: 159 | FE2: 160 | FF2: 161 | FG2: 162 | FH2: 163 | FI2: 164 | FJ2: 165 | FK2: 166 | FL2: 167 | FM2: 168 | FN2: 169 | FO2: 170 | FP2: 171 | FQ2: 172 | FR2: 173 | FS2: 174 | FT2: 175 | FU2: 176 | FV2: 177 | FW2: 178 | FX2: 179 | FY2: 180
A3: 1 | B3: 0 | C3: 0 | D3: 0 | E3: 0 | F3: 0 | G3: 0 | H3: 0 | I3: 0 | J3: 0 | K3: 0 | L3: 0 | M3: 0 | N3: 0 | O3: 0 | P3: 0 | Q3: 0 | R3: 0 | S3: 0 | T3: 0 | U3: 0 | V3: 0 | W3: 0 | X3: 0 | Y3: 0 | Z3: 0 | AA3: 0 | AB3: 0 | AC3: 0 | AD3: 0 | AE3: 0 | AF3: 0 | AG3: 0 | AH3: 0 | AI3: 0 | AJ3: 0 | AK3: 0 | AL3: 0 | AM3: 0 | AN3: 0 | AO3: 0 | AP3: 0 | AQ3: 0 | AR3: 0 | AS3: 0 | AT3: 0 | AU3: 0 | AV3: 0 | AW3: 0 | AX3: 0 | AY3: 0 | AZ3: 0 | BA3: 0 | BB3: 0 | BC3: 0 | BD3: 0 | BE3: 0 | BF3: 0 | BG3: 0 | BH3: 0 | BI3: 0 | BJ3: 0 | BK3: 0 | BL3: 0 | BM3: 0 | BN3: 0 | BO3: 0 | BP3: 0 | BQ3: 0 | BR3: 0 | BS3: 0 | BT3: 0 | BU3: 0 | BV3: 0 | BW3: 0 | BX3: 0 | BY3: 0 | BZ3: 0 | CA3: 0 | CB3: 0 | CC3: 0 | CD3: 0 | CE3: 0 | CF3: 0 | CG3: 0 | CH3: 0 | CI3: 0 | CJ3: 0 | CK3: 0 | CL3: 0 | CM3: 0 | CN3: 0 | CO3: 0 | CP3: 0 | CQ3: 0 | CR3: 0 | CS3: 0 | CT3: 0 | CU3: 0 | CV3: 0 | CW3: 0 | CX3: 0 | CY3: 0 | CZ3: 0 | DA3: 0 | DB3: 0 | DC3: 0 | DD3: 0 | DE3: 0 | DF3: 0 | DG3: 0 | DH3: 0 | DI3: 0 | DJ3: 0 | DK3: 0 | DL3: 0 | DM3: 0 | DN3: 0 | DO3: 0 | DP3: 0 | DQ3: 0 | DR3: 0 | DS3: 0 | DT3: 0 | DU3: 0 | DV3: 0 | DW3: 0 | DX3: 0 | DY3: 0 | DZ3: 0 | EA3: 0 | EB3: 0 | EC3: 0 | ED3: 0 | EE3: 0 | EF3: 0 | EG3: 0 | EH3: 0 | EI3: 0 | EJ3: 0 | EK3: 0 | EL3: 0 | EM3: 0 | EN3: 0 | EO3: 0 | EP3: 0 | EQ3: 0 | ER3: 0 | ES3: 0 | ET3: 0 | EU3: 0 | EV3: 0 | EW3: 0 | EX3: 0 | EY3: 0 | EZ3: 0 | FA3: 0 | FB3: 0 | FC3: 0 | FD3: 0 | FE3: 0 | FF3: 0 | FG3: 0 | FH3: 0 | FI3: 0 | FJ3: 0 | FK3: 0 | FL3: 0 | FM3: 0 | FN3: 0 | FO3: 0 | FP3: 0 | FQ3: 0 | FR3: 0 | FS3: 0 | FT3: 0 | FU3: 0 | FV3: 0 | FW3: 0 | FX3: 0 | FY3: 0
A4: 2 | B4: 3000 | C4: 3000 | D4: 3000 | E4: 3000 | F4: 3000 | G4: 3000 | H4: 3000 | I4: 3000 | J4: 3000 | K4: 3000 | L4: 3000 | M4: 3000 | N4: 3000 | O4: 3000 | P4: 3000 | Q4: 3000 | R4: 3000 | S4: 3000 | T4: 3000 | U4: 3000 | V4: 3000 | W4: 3000 | X4: 3000 | Y4: 3000 | Z4: 3000 | AA4: 3000 | AB4: 3000 | AC4: 3000 | AD4: 3000 | AE4: 3000 | AF4: 3000 | AG4: 3000 | AH4: 3000 | AI4: 3000 | AJ4: 3000 | AK4: 3000 | AL4: 3000 | AM4: 3000 | AN4: 3000 | AO4: 3000 | AP4: 3000 | AQ4: 3000 | AR4: 3000 | AS4: 3000 | AT4: 3000 | AU4: 3000 | AV4: 3000 | AW4: 3000 | AX4: 3000 | AY4: 3000 | AZ4: 3000 | BA4: 3000 | BB4: 3000 | BC4: 3000 | BD4: 3000 | BE4: 3000 | BF4: 3000 | BG4: 3000 | BH4: 3000 | BI4: 3000 | BJ4: 3000 | BK4: 3000 | BL4: 3000 | BM4: 3000 | BN4: 3000 | BO4: 3000 | BP4: 3000 | BQ4: 3000 | BR4: 3000 | BS4: 3000 | BT4: 3000 | BU4: 3000 | BV4: 3000 | BW4: 3000 | BX4: 3000 | BY4: 3000 | BZ4: 3000 | CA4: 3000 | CB4: 3000 | CC4: 3000 | CD4: 3000 | CE4: 3000 | CF4: 3000 | CG4: 3000 | CH4: 3000 | CI4: 3000 | CJ4: 3000 | CK4: 3000 | CL4: 3000 | CM4: 3000 | CN4: 3000 | CO4: 3000 | CP4: 3000 | CQ4: 3000 | CR4: 3000 | CS4: 3000 | CT4: 3000 | CU4: 3000 | CV4: 3000 | CW4: 3000 | CX4: 3000 | CY4: 3000 | CZ4: 3000 | DA4: 3000 | DB4: 3000 | DC4: 3000 | DD4: 3000 | DE4: 3000 | DF4: 3000 | DG4: 3000 | DH4: 3000 | DI4: 3000 | DJ4: 3000 | DK4: 3000 | DL4: 3000 | DM4: 3000 | DN4: 3000 | DO4: 3000 | DP4: 3000 | DQ4: 3000 | DR4: 3000 | DS4: 3000 | DT4: 3000 | DU4: 3000 | DV4: 3000 | DW4: 3000 | DX4: 3000 | DY4: 3000 | DZ4: 3000 | EA4: 3000 | EB4: 3000 | EC4: 3000 | ED4: 3000 | EE4: 3000 | EF4: 3000 | EG4: 3000 | EH4: 3000 | EI4: 3000 | EJ4: 3000 | EK4: 3000 | EL4: 3000 | EM4: 3000 | EN4: 3000 | EO4: 3000 | EP4: 3000 | EQ4: 3000 | ER4: 3000 | ES4: 3000 | ET4: 3000 | EU4: 3000 | EV4: 3000 | EW4: 3000 | EX4: 3000 | EY4: 3000 | EZ4: 3000 | FA4: 3000 | FB4: 3000 | FC4: 3000 | FD4: 3000 | FE4: 3000 | FF4: 3000 | FG4: 3000 | FH4: 3000 | FI4: 3000 | FJ4: 3000 | FK4: 3000 | FL4: 3000 | FM4: 3000 | FN4: 3000 | FO4: 3000 | FP4: 3000 | FQ4: 3000 | FR4: 3000 | FS4: 3000 | FT4: 3000 | FU4: 3000 | FV4: 3000 | FW4: 3000 | FX4: 3000 | FY4: 3000
A5: 3 | B5: 6000 | C5: 6000 | D5: 6000 | E5: 6000 | F5: 6000 | G5: 6000 | H5: 6000 | I5: 6000 | J5: 6000 | K5: 6000 | L5: 6000 | M5: 6000 | N5: 6000 | O5: 6000 | P5: 6000 | Q5: 6000 | R5: 6000 | S5: 6000 | T5: 6000 | U5: 6000 | V5: 6000 | W5: 6000 | X5: 6000 | Y5: 6000 | Z5: 6000 | AA5: 6000 | AB5: 6000 | AC5: 6000 | AD5: 6000 | AE5: 6000 | AF5: 6000 | AG5: 6000 | AH5: 6000 | AI5: 6000 | AJ5: 6000 | AK5: 6000 | AL5: 6000 | AM5: 6000 | AN5: 6000 | AO5: 6000 | AP5: 6000 | AQ5: 6000 | AR5: 6000 | AS5: 6000 | AT5: 6000 | AU5: 6000 | AV5: 6000 | AW5: 6000 | AX5: 6000 | AY5: 6000 | AZ5: 6000 | BA5: 6000 | BB5: 6000 | BC5: 6000 | BD5: 6000 | BE5: 6000 | BF5: 6000 | BG5: 6000 | BH5: 6000 | BI5: 6000 | BJ5: 6000 | BK5: 6000 | BL5: 6000 | BM5: 6000 | BN5: 6000 | BO5: 6000 | BP5: 6000 | BQ5: 6000 | BR5: 6000 | BS5: 6000 | BT5: 6000 | BU5: 6000 | BV5: 6000 | BW5: 6000 | BX5: 6000 | BY5: 6000 | BZ5: 6000 | CA5: 6000 | CB5: 6000 | CC5: 6000 | CD5: 6000 | CE5: 6000 | CF5: 6000 | CG5: 6000 | CH5: 6000 | CI5: 6000 | CJ5: 6000 | CK5: 6000 | CL5: 6000 | CM5: 6000 | CN5: 6000 | CO5: 6000 | CP5: 6000 | CQ5: 6000 | CR5: 6000 | CS5: 6000 | CT5: 6000 | CU5: 6000 | CV5: 6000 | CW5: 6000 | CX5: 6000 | CY5: 6000 | CZ5: 6000 | DA5: 6000 | DB5: 6000 | DC5: 6000 | DD5: 6000 | DE5: 6000 | DF5: 6000 | DG5: 6000 | DH5: 6000 | DI5: 6000 | DJ5: 6000 | DK5: 6000 | DL5: 6000 | DM5: 6000 | DN5: 6000 | DO5: 6000 | DP5: 6000 | DQ5: 6000 | DR5: 6000 | DS5: 6000 | DT5: 6000 | DU5: 6000 | DV5: 6000 | DW5: 6000 | DX5: 6000 | DY5: 6000 | DZ5: 6000 | EA5: 6000 | EB5: 6000 | EC5: 6000 | ED5: 6000 | EE5: 6000 | EF5: 6000 | EG5: 6000 | EH5: 6000 | EI5: 6000 | EJ5: 6000 | EK5: 6000 | EL5: 6000 | EM5: 6000 | EN5: 6000 | EO5: 6000 | EP5: 6000 | EQ5: 6000 | ER5: 6000 | ES5: 6000 | ET5: 6000 | EU5: 6000 | EV5: 6000 | EW5: 6000 | EX5: 6000 | EY5: 6000 | EZ5: 6000 | FA5: 6000 | FB5: 6000 | FC5: 6000 | FD5: 6000 | FE5: 6000 | FF5: 6000 | FG5: 6000 | FH5: 6000 | FI5: 6000 | FJ5: 6000 | FK5: 6000 | FL5: 6000 | FM5: 6000 | FN5: 6000 | FO5: 6000 | FP5: 6000 | FQ5: 6000 | FR5: 6000 | FS5: 6000 | FT5: 6000 | FU5: 6000 | FV5: 6000 | FW5: 6000 | FX5: 6000 | FY5: 6000

Sheet CGij
A1: j/i | B1: Tower i | AP1: 2057.1429
A2: Electrode cost j | B2: 1 | C2: 2 | D2: 3 | E2: 4 | F2: 5 | G2: 6 | H2: 7 | I2: 8 | J2: 9 | K2: 10 | L2: 11 | M2: 12 | N2: 13 | O2: 14 | P2: 15 | Q2: 16 | R2: 17 | S2: 18 | T2: 19 | U2: 20 | V2: 21 | W2: 22 | X2: 23 | Y2: 24 | Z2: 25 | AA2: 26 | AB2: 27 | AC2: 28 | AD2: 29 | AE2: 30 | AF2: 31 | AG2: 32 | AH2: 33 | AI2: 34 | AJ2: 35 | AK2: 36 | AL2: 37 | AM2: 38 | AN2: 39 | AO2: 40 | AP2: 41 | AQ2: 42 | AR2: 43 | AS2: 44 | AT2: 45 | AU2: 46 | AV2: 47 | AW2: 48 | AX2: 49 | AY2: 50 | AZ2: 51 | BA2: 52 | BB2: 53 | BC2: 54 | BD2: 55 | BE2: 56 | BF2: 57 | BG2: 58 | BH2: 59 | BI2: 60 | BJ2: 61 | BK2: 62 | BL2: 63 | BM2: 64 | BN2: 65 | BO2: 66 | BP2: 67 | BQ2: 68 | BR2: 69 | BS2: 70 | BT2: 71 | BU2: 72 | BV2: 73 | BW2: 74 | BX2: 75 | BY2: 76 | BZ2: 77 | CA2: 78 | CB2: 79 | CC2: 80 | CD2: 81 | CE2: 82 | CF2: 83 | CG2: 84 | CH2: 85 | CI2: 86 | CJ2: 87 | CK2: 88 | CL2: 89 | CM2: 90 | CN2: 91 | CO2: 92 | CP2: 93 | CQ2: 94 | CR2: 95 | CS2: 96 | CT2: 97 | CU2: 98 | CV2: 99 | CW2: 100 | CX2: 101 | CY2: 102 | CZ2: 103 | DA2: 104 | DB2: 105 | DC2: 106 | DD2: 107 | DE2: 108 | DF2: 109 | DG2: 110 | DH2: 111 | DI2: 112 | DJ2: 113 | DK2: 114 | DL2: 115 | DM2: 116 | DN2: 117 | DO2: 118 | DP2: 119 | DQ2: 120 | DR2: 121 | DS2: 122 | DT2: 123 | DU2: 124 | DV2: 125 | DW2: 126 | DX2: 127 | DY2: 128 | DZ2: 129 | EA2: 130 | EB2: 131 | EC2: 132 | ED2: 133 | EE2: 134 | EF2: 135 | EG2: 136 | EH2: 137 | EI2: 138 | EJ2: 139 | EK2: 140 | EL2: 141 | EM2: 142 | EN2: 143 | EO2: 144 | EP2: 145 | EQ2: 146 | ER2: 147 | ES2: 148 | ET2: 149 | EU2: 150 | EV2: 151 | EW2: 152 | EX2: 153 | EY2: 154 | EZ2: 155 | FA2: 156 | FB2: 157 | FC2: 158 | FD2: 159 | FE2: 160 | FF2: 161 | FG2: 162 | FH2: 163 | FI2: 164 | FJ2: 165 | FK2: 166 | FL2: 167 | FM2: 168 | FN2: 169 | FO2: 170 | FP2: 171 | FQ2: 172 | FR2: 173 | FS2: 174 | FT2: 175 | FU2: 176 | FV2: 177 | FW2: 178 | FX2: 179 | FY2: 180
A3: 1 | B3: 0 | C3: 0 | D3: 0 | E3: 0 | F3: 0 | G3: 0 | H3: 0 | I3: 0 | J3: 0 | K3: 0 | L3: 0 | M3: 0 | N3: 0 | O3: 0 | P3: 0 | Q3: 0 | R3: 0 | S3: 0 | T3: 0 | U3: 0 | V3: 0 | W3: 0 | X3: 0 | Y3: 0 | Z3: 0 | AA3: 0 | AB3: 0 | AC3: 0 | AD3: 0 | AE3: 0 | AF3: 0 | AG3: 0 | AH3: 0 | AI3: 0 | AJ3: 0 | AK3: 0 | AL3: 0 | AM3: 0 | AN3: 0 | AO3: 0 | AP3: 0 | AQ3: 0 | AR3: 0 | AS3: 0 | AT3: 0 | AU3: 0 | AV3: 0 | AW3: 0 | AX3: 0 | AY3: 0 | AZ3: 0 | BA3: 0 | BB3: 0 | BC3: 0 | BD3: 0 | BE3: 0 | BF3: 0 | BG3: 0 | BH3: 0 | BI3: 0 | BJ3: 0 | BK3: 0 | BL3: 0 | BM3: 0 | BN3: 0 | BO3: 0 | BP3: 0 | BQ3: 0 | BR3: 0 | BS3: 0 | BT3: 0 | BU3: 0 | BV3: 0 | BW3: 0 | BX3: 0 | BY3: 0 | BZ3: 0 | CA3: 0 | CB3: 0 | CC3: 0 | CD3: 0 | CE3: 0 | CF3: 0 | CG3: 0 | CH3: 0 | CI3: 0 | CJ3: 0 | CK3: 0 | CL3: 0 | CM3: 0 | CN3: 0 | CO3: 0 | CP3: 0 | CQ3: 0 | CR3: 0 | CS3: 0 | CT3: 0 | CU3: 0 | CV3: 0 | CW3: 0 | CX3: 0 | CY3: 0 | CZ3: 0 | DA3: 0 | DB3: 0 | DC3: 0 | DD3: 0 | DE3: 0 | DF3: 0 | DG3: 0 | DH3: 0 | DI3: 0 | DJ3: 0 | DK3: 0 | DL3: 0 | DM3: 0 | DN3: 0 | DO3: 0 | DP3: 0 | DQ3: 0 | DR3: 0 | DS3: 0 | DT3: 0 | DU3: 0 | DV3: 0 | DW3: 0 | DX3: 0 | DY3: 0 | DZ3: 0 | EA3: 0 | EB3: 0 | EC3: 0 | ED3: 0 | EE3: 0 | EF3: 0 | EG3: 0 | EH3: 0 | EI3: 0 | EJ3: 0 | EK3: 0 | EL3: 0 | EM3: 0 | EN3: 0 | EO3: 0 | EP3: 0 | EQ3: 0 | ER3: 0 | ES3: 0 | ET3: 0 | EU3: 0 | EV3: 0 | EW3: 0 | EX3: 0 | EY3: 0 | EZ3: 0 | FA3: 0 | FB3: 0 | FC3: 0 | FD3: 0 | FE3: 0 | FF3: 0 | FG3: 0 | FH3: 0 | FI3: 0 | FJ3: 0 | FK3: 0 | FL3: 0 | FM3: 0 | FN3: 0 | FO3: 0 | FP3: 0 | FQ3: 0 | FR3: 0 | FS3: 0 | FT3: 0 | FU3: 0 | FV3: 0 | FW3: 0 | FX3: 0 | FY3: 0
A4: 2 | B4: 171.42857 | C4: 171.42857 | D4: 171.42857 | E4: 171.42857 | F4: 171.42857 | G4: 171.42857 | H4: 171.42857 | I4: 171.42857 | J4: 171.42857 | K4: 171.42857 | L4: 171.42857 | M4: 171.42857 | N4: 171.42857 | O4: 171.42857 | P4: 171.42857 | Q4: 171.42857 | R4: 171.42857 | S4: 171.42857 | T4: 171.42857 | U4: 171.42857 | V4: 171.42857 | W4: 171.42857 | X4: 171.42857 | Y4: 171.42857 | Z4: 171.42857 | AA4: 171.42857 | AB4: 171.42857 | AC4: 171.42857 | AD4: 171.42857 | AE4: 171.42857 | AF4: 171.42857 | AG4: 171.42857 | AH4: 171.42857 | AI4: 171.42857 | AJ4: 171.42857 | AK4: 171.42857 | AL4: 171.42857 | AM4: 171.42857 | AN4: 171.42857 | AO4: 171.42857 | AP4: 171.42857 | AQ4: 171.42857 | AR4: 171.42857 | AS4: 171.42857 | AT4: 171.42857 | AU4: 171.42857 | AV4: 171.42857 | AW4: 171.42857 | AX4: 171.42857 | AY4: 171.42857 | AZ4: 171.42857 | BA4: 171.42857 | BB4: 171.42857 | BC4: 171.42857 | BD4: 171.42857 | BE4: 171.42857 | BF4: 171.42857 | BG4: 171.42857 | BH4: 171.42857 | BI4: 171.42857 | BJ4: 171.42857 | BK4: 171.42857 | BL4: 171.42857 | BM4: 171.42857 | BN4: 171.42857 | BO4: 171.42857 | BP4: 171.42857 | BQ4: 171.42857 | BR4: 171.42857 | BS4: 171.42857 | BT4: 171.42857 | BU4: 171.42857 | BV4: 171.42857 | BW4: 171.42857 | BX4: 171.42857 | BY4: 171.42857 | BZ4: 171.42857 | CA4: 171.42857 | CB4: 171.42857 | CC4: 171.42857 | CD4: 171.42857 | CE4: 171.42857 | CF4: 171.42857 | CG4: 171.42857 | CH4: 171.42857 | CI4: 171.42857 | CJ4: 171.42857 | CK4: 171.42857 | CL4: 171.42857 | CM4: 171.42857 | CN4: 171.42857 | CO4: 171.42857 | CP4: 171.42857 | CQ4: 171.42857 | CR4: 171.42857 | CS4: 171.42857 | CT4: 171.42857 | CU4: 171.42857 | CV4: 171.42857 | CW4: 171.42857 | CX4: 171.42857 | CY4: 171.42857 | CZ4: 171.42857 | DA4: 171.42857 | DB4: 171.42857 | DC4: 171.42857 | DD4: 171.42857 | DE4: 171.42857 | DF4: 171.42857 | DG4: 171.42857 | DH4: 171.42857 | DI4: 171.42857 | DJ4: 171.42857 | DK4: 171.42857 | DL4: 171.42857 | DM4: 171.42857 | DN4: 171.42857 | DO4: 171.42857 | DP4: 171.42857 | DQ4: 171.42857 | DR4: 171.42857 | DS4: 171.42857 | DT4: 171.42857 | DU4: 171.42857 | DV4: 171.42857 | DW4: 171.42857 | DX4: 171.42857 | DY4: 171.42857 | DZ4: 171.42857 | EA4: 171.42857 | EB4: 171.42857 | EC4: 171.42857 | ED4: 171.42857 | EE4: 171.42857 | EF4: 171.42857 | EG4: 171.42857 | EH4: 171.42857 | EI4: 171.42857 | EJ4: 171.42857 | EK4: 171.42857 | EL4: 171.42857 | EM4: 171.42857 | EN4: 171.42857 | EO4: 171.42857 | EP4: 171.42857 | EQ4: 171.42857 | ER4: 171.42857 | ES4: 171.42857 | ET4: 171.42857 | EU4: 171.42857 | EV4: 171.42857 | EW4: 171.42857 | EX4: 171.42857 | EY4: 171.42857 | EZ4: 171.42857 | FA4: 171.42857 | FB4: 171.42857 | FC4: 171.42857 | FD4: 171.42857 | FE4: 171.42857 | FF4: 171.42857 | FG4: 171.42857 | FH4: 171.42857 | FI4: 171.42857 | FJ4: 171.42857 | FK4: 171.42857 | FL4: 171.42857 | FM4: 171.42857 | FN4: 171.42857 | FO4: 171.42857 | FP4: 171.42857 | FQ4: 171.42857 | FR4: 171.42857 | FS4: 171.42857 | FT4: 171.42857 | FU4: 171.42857 | FV4: 171.42857 | FW4: 171.42857 | FX4: 171.42857 | FY4: 171.42857
A5: 3 | B5: 342.85714 | C5: 342.85714 | D5: 342.85714 | E5: 342.85714 | F5: 342.85714 | G5: 342.85714 | H5: 342.85714 | I5: 342.85714 | J5: 342.85714 | K5: 342.85714 | L5: 342.85714 | M5: 342.85714 | N5: 342.85714 | O5: 342.85714 | P5: 342.85714 | Q5: 342.85714 | R5: 342.85714 | S5: 342.85714 | T5: 342.85714 | U5: 342.85714 | V5: 342.85714 | W5: 342.85714 | X5: 342.85714 | Y5: 342.85714 | Z5: 342.85714 | AA5: 342.85714 | AB5: 342.85714 | AC5: 342.85714 | AD5: 342.85714 | AE5: 342.85714 | AF5: 342.85714 | AG5: 342.85714 | AH5: 342.85714 | AI5: 342.85714 | AJ5: 342.85714 | AK5: 342.85714 | AL5: 342.85714 | AM5: 342.85714 | AN5: 342.85714 | AO5: 342.85714 | AP5: 342.85714 | AQ5: 342.85714 | AR5: 342.85714 | AS5: 342.85714 | AT5: 342.85714 | AU5: 342.85714 | AV5: 342.85714 | AW5: 342.85714 | AX5: 342.85714 | AY5: 342.85714 | AZ5: 342.85714 | BA5: 342.85714 | BB5: 342.85714 | BC5: 342.85714 | BD5: 342.85714 | BE5: 342.85714 | BF5: 342.85714 | BG5: 342.85714 | BH5: 342.85714 | BI5: 342.85714 | BJ5: 342.85714 | BK5: 342.85714 | BL5: 342.85714 | BM5: 342.85714 | BN5: 342.85714 | BO5: 342.85714 | BP5: 342.85714 | BQ5: 342.85714 | BR5: 342.85714 | BS5: 342.85714 | BT5: 342.85714 | BU5: 342.85714 | BV5: 342.85714 | BW5: 342.85714 | BX5: 342.85714 | BY5: 342.85714 | BZ5: 342.85714 | CA5: 342.85714 | CB5: 342.85714 | CC5: 342.85714 | CD5: 342.85714 | CE5: 342.85714 | CF5: 342.85714 | CG5: 342.85714 | CH5: 342.85714 | CI5: 342.85714 | CJ5: 342.85714 | CK5: 342.85714 | CL5: 342.85714 | CM5: 342.85714 | CN5: 342.85714 | CO5: 342.85714 | CP5: 342.85714 | CQ5: 342.85714 | CR5: 342.85714 | CS5: 342.85714 | CT5: 342.85714 | CU5: 342.85714 | CV5: 342.85714 | CW5: 342.85714 | CX5: 342.85714 | CY5: 342.85714 | CZ5: 342.85714 | DA5: 342.85714 | DB5: 342.85714 | DC5: 342.85714 | DD5: 342.85714 | DE5: 342.85714 | DF5: 342.85714 | DG5: 342.85714 | DH5: 342.85714 | DI5: 342.85714 | DJ5: 342.85714 | DK5: 342.85714 | DL5: 342.85714 | DM5: 342.85714 | DN5: 342.85714 | DO5: 342.85714 | DP5: 342.85714 | DQ5: 342.85714 | DR5: 342.85714 | DS5: 342.85714 | DT5: 342.85714 | DU5: 342.85714 | DV5: 342.85714 | DW5: 342.85714 | DX5: 342.85714 | DY5: 342.85714 | DZ5: 342.85714 | EA5: 342.85714 | EB5: 342.85714 | EC5: 342.85714 | ED5: 342.85714 | EE5: 342.85714 | EF5: 342.85714 | EG5: 342.85714 | EH5: 342.85714 | EI5: 342.85714 | EJ5: 342.85714 | EK5: 342.85714 | EL5: 342.85714 | EM5: 342.85714 | EN5: 342.85714 | EO5: 342.85714 | EP5: 342.85714 | EQ5: 342.85714 | ER5: 342.85714 | ES5: 342.85714 | ET5: 342.85714 | EU5: 342.85714 | EV5: 342.85714 | EW5: 342.85714 | EX5: 342.85714 | EY5: 342.85714 | EZ5: 342.85714 | FA5: 342.85714 | FB5: 342.85714 | FC5: 342.85714 | FD5: 342.85714 | FE5: 342.85714 | FF5: 342.85714 | FG5: 342.85714 | FH5: 342.85714 | FI5: 342.85714 | FJ5: 342.85714 | FK5: 342.85714 | FL5: 342.85714 | FM5: 342.85714 | FN5: 342.85714 | FO5: 342.85714 | FP5: 342.85714 | FQ5: 342.85714 | FR5: 342.85714 | FS5: 342.85714 | FT5: 342.85714 | FU5: 342.85714 | FV5: 342.85714 | FW5: 342.85714 | FX5: 342.85714 | FY5: 342.85714
A6: 4 | B6: 514.28571 | C6: 514.28571 | D6: 514.28571 | E6: 514.28571 | F6: 514.28571 | G6: 514.28571 | H6: 514.28571 | I6: 514.28571 | J6: 514.28571 | K6: 514.28571 | L6: 514.28571 | M6: 514.28571 | N6: 514.28571 | O6: 514.28571 | P6: 514.28571 | Q6: 514.28571 | R6: 514.28571 | S6: 514.28571 | T6: 514.28571 | U6: 514.28571 | V6: 514.28571 | W6: 514.28571 | X6: 514.28571 | Y6: 514.28571 | Z6: 514.28571 | AA6: 514.28571 | AB6: 514.28571 | AC6: 514.28571 | AD6: 514.28571 | AE6: 514.28571 | AF6: 514.28571 | AG6: 514.28571 | AH6: 514.28571 | AI6: 514.28571 | AJ6: 514.28571 | AK6: 514.28571 | AL6: 514.28571 | AM6: 514.28571 | AN6: 514.28571 | AO6: 514.28571 | AP6: 514.28571 | AQ6: 514.28571 | AR6: 514.28571 | AS6: 514.28571 | AT6: 514.28571 | AU6: 514.28571 | AV6: 514.28571 | AW6: 514.28571 | AX6: 514.28571 | AY6: 514.28571 | AZ6: 514.28571 | BA6: 514.28571 | BB6: 514.28571 | BC6: 514.28571 | BD6: 514.28571 | BE6: 514.28571 | BF6: 514.28571 | BG6: 514.28571 | BH6: 514.28571 | BI6: 514.28571 | BJ6: 514.28571 | BK6: 514.28571 | BL6: 514.28571 | BM6: 514.28571 | BN6: 514.28571 | BO6: 514.28571 | BP6: 514.28571 | BQ6: 514.28571 | BR6: 514.28571 | BS6: 514.28571 | BT6: 514.28571 | BU6: 514.28571 | BV6: 514.28571 | BW6: 514.28571 | BX6: 514.28571 | BY6: 514.28571 | BZ6: 514.28571 | CA6: 514.28571 | CB6: 514.28571 | CC6: 514.28571 | CD6: 514.28571 | CE6: 514.28571 | CF6: 514.28571 | CG6: 514.28571 | CH6: 514.28571 | CI6: 514.28571 | CJ6: 514.28571 | CK6: 514.28571 | CL6: 514.28571 | CM6: 514.28571 | CN6: 514.28571 | CO6: 514.28571 | CP6: 514.28571 | CQ6: 514.28571 | CR6: 514.28571 | CS6: 514.28571 | CT6: 514.28571 | CU6: 514.28571 | CV6: 514.28571 | CW6: 514.28571 | CX6: 514.28571 | CY6: 514.28571 | CZ6: 514.28571 | DA6: 514.28571 | DB6: 514.28571 | DC6: 514.28571 | DD6: 514.28571 | DE6: 514.28571 | DF6: 514.28571 | DG6: 514.28571 | DH6: 514.28571 | DI6: 514.28571 | DJ6: 514.28571 | DK6: 514.28571 | DL6: 514.28571 | DM6: 514.28571 | DN6: 514.28571 | DO6: 514.28571 | DP6: 514.28571 | DQ6: 514.28571 | DR6: 514.28571 | DS6: 514.28571 | DT6: 514.28571 | DU6: 514.28571 | DV6: 514.28571 | DW6: 514.28571 | DX6: 514.28571 | DY6: 514.28571 | DZ6: 514.28571 | EA6: 514.28571 | EB6: 514.28571 | EC6: 514.28571 | ED6: 514.28571 | EE6: 514.28571 | EF6: 514.28571 | EG6: 514.28571 | EH6: 514.28571 | EI6: 514.28571 | EJ6: 514.28571 | EK6: 514.28571 | EL6: 514.28571 | EM6: 514.28571 | EN6: 514.28571 | EO6: 514.28571 | EP6: 514.28571 | EQ6: 514.28571 | ER6: 514.28571 | ES6: 514.28571 | ET6: 514.28571 | EU6: 514.28571 | EV6: 514.28571 | EW6: 514.28571 | EX6: 514.28571 | EY6: 514.28571 | EZ6: 514.28571 | FA6: 514.28571 | FB6: 514.28571 | FC6: 514.28571 | FD6: 514.28571 | FE6: 514.28571 | FF6: 514.28571 | FG6: 514.28571 | FH6: 514.28571 | FI6: 514.28571 | FJ6: 514.28571 | FK6: 514.28571 | FL6: 514.28571 | FM6: 514.28571 | FN6: 514.28571 | FO6: 514.28571 | FP6: 514.28571 | FQ6: 514.28571 | FR6: 514.28571 | FS6: 514.28571 | FT6: 514.28571 | FU6: 514.28571 | FV6: 514.28571 | FW6: 514.28571 | FX6: 514.28571 | FY6: 514.28571
A7: 5 | B7: 685.71429 | C7: 685.71429 | D7: 685.71429 | E7: 685.71429 | F7: 685.71429 | G7: 685.71429 | H7: 685.71429 | I7: 685.71429 | J7: 685.71429 | K7: 685.71429 | L7: 685.71429 | M7: 685.71429 | N7: 685.71429 | O7: 685.71429 | P7: 685.71429 | Q7: 685.71429 | R7: 685.71429 | S7: 685.71429 | T7: 685.71429 | U7: 685.71429 | V7: 685.71429 | W7: 685.71429 | X7: 685.71429 | Y7: 685.71429 | Z7: 685.71429 | AA7: 685.71429 | AB7: 685.71429 | AC7: 685.71429 | AD7: 685.71429 | AE7: 685.71429 | AF7: 685.71429 | AG7: 685.71429 | AH7: 685.71429 | AI7: 685.71429 | AJ7: 685.71429 | AK7: 685.71429 | AL7: 685.71429 | AM7: 685.71429 | AN7: 685.71429 | AO7: 685.71429 | AP7: 685.71429 | AQ7: 685.71429 | AR7: 685.71429 | AS7: 685.71429 | AT7: 685.71429 | AU7: 685.71429 | AV7: 685.71429 | AW7: 685.71429 | AX7: 685.71429 | AY7: 685.71429 | AZ7: 685.71429 | BA7: 685.71429 | BB7: 685.71429 | BC7: 685.71429 | BD7: 685.71429 | BE7: 685.71429 | BF7: 685.71429 | BG7: 685.71429 | BH7: 685.71429 | BI7: 685.71429 | BJ7: 685.71429 | BK7: 685.71429 | BL7: 685.71429 | BM7: 685.71429 | BN7: 685.71429 | BO7: 685.71429 | BP7: 685.71429 | BQ7: 685.71429 | BR7: 685.71429 | BS7: 685.71429 | BT7: 685.71429 | BU7: 685.71429 | BV7: 685.71429 | BW7: 685.71429 | BX7: 685.71429 | BY7: 685.71429 | BZ7: 685.71429 | CA7: 685.71429 | CB7: 685.71429 | CC7: 685.71429 | CD7: 685.71429 | CE7: 685.71429 | CF7: 685.71429 | CG7: 685.71429 | CH7: 685.71429 | CI7: 685.71429 | CJ7: 685.71429 | CK7: 685.71429 | CL7: 685.71429 | CM7: 685.71429 | CN7: 685.71429 | CO7: 685.71429 | CP7: 685.71429 | CQ7: 685.71429 | CR7: 685.71429 | CS7: 685.71429 | CT7: 685.71429 | CU7: 685.71429 | CV7: 685.71429 | CW7: 685.71429 | CX7: 685.71429 | CY7: 685.71429 | CZ7: 685.71429 | DA7: 685.71429 | DB7: 685.71429 | DC7: 685.71429 | DD7: 685.71429 | DE7: 685.71429 | DF7: 685.71429 | DG7: 685.71429 | DH7: 685.71429 | DI7: 685.71429 | DJ7: 685.71429 | DK7: 685.71429 | DL7: 685.71429 | DM7: 685.71429 | DN7: 685.71429 | DO7: 685.71429 | DP7: 685.71429 | DQ7: 685.71429 | DR7: 685.71429 | DS7: 685.71429 | DT7: 685.71429 | DU7: 685.71429 | DV7: 685.71429 | DW7: 685.71429 | DX7: 685.71429 | DY7: 685.71429 | DZ7: 685.71429 | EA7: 685.71429 | EB7: 685.71429 | EC7: 685.71429 | ED7: 685.71429 | EE7: 685.71429 | EF7: 685.71429 | EG7: 685.71429 | EH7: 685.71429 | EI7: 685.71429 | EJ7: 685.71429 | EK7: 685.71429 | EL7: 685.71429 | EM7: 685.71429 | EN7: 685.71429 | EO7: 685.71429 | EP7: 685.71429 | EQ7: 685.71429 | ER7: 685.71429 | ES7: 685.71429 | ET7: 685.71429 | EU7: 685.71429 | EV7: 685.71429 | EW7: 685.71429 | EX7: 685.71429 | EY7: 685.71429 | EZ7: 685.71429 | FA7: 685.71429 | FB7: 685.71429 | FC7: 685.71429 | FD7: 685.71429 | FE7: 685.71429 | FF7: 685.71429 | FG7: 685.71429 | FH7: 685.71429 | FI7: 685.71429 | FJ7: 685.71429 | FK7: 685.71429 | FL7: 685.71429 | FM7: 685.71429 | FN7: 685.71429 | FO7: 685.71429 | FP7: 685.71429 | FQ7: 685.71429 | FR7: 685.71429 | FS7: 685.71429 | FT7: 685.71429 | FU7: 685.71429 | FV7: 685.71429 | FW7: 685.71429 | FX7: 685.71429 | FY7: 685.71429
A8: 6 | B8: 857.14286 | C8: 857.14286 | D8: 857.14286 | E8: 857.14286 | F8: 857.14286 | G8: 857.14286 | H8: 857.14286 | I8: 857.14286 | J8: 857.14286 | K8: 857.14286 | L8: 857.14286 | M8: 857.14286 | N8: 857.14286 | O8: 857.14286 | P8: 857.14286 | Q8: 857.14286 | R8: 857.14286 | S8: 857.14286 | T8: 857.14286 | U8: 857.14286 | V8: 857.14286 | W8: 857.14286 | X8: 857.14286 | Y8: 857.14286 | Z8: 857.14286 | AA8: 857.14286 | AB8: 857.14286 | AC8: 857.14286 | AD8: 857.14286 | AE8: 857.14286 | AF8: 857.14286 | AG8: 857.14286 | AH8: 857.14286 | AI8: 857.14286 | AJ8: 857.14286 | AK8: 857.14286 | AL8: 857.14286 | AM8: 857.14286 | AN8: 857.14286 | AO8: 857.14286 | AP8: 857.14286 | AQ8: 857.14286 | AR8: 857.14286 | AS8: 857.14286 | AT8: 857.14286 | AU8: 857.14286 | AV8: 857.14286 | AW8: 857.14286 | AX8: 857.14286 | AY8: 857.14286 | AZ8: 857.14286 | BA8: 857.14286 | BB8: 857.14286 | BC8: 857.14286 | BD8: 857.14286 | BE8: 857.14286 | BF8: 857.14286 | BG8: 857.14286 | BH8: 857.14286 | BI8: 857.14286 | BJ8: 857.14286 | BK8: 857.14286 | BL8: 857.14286 | BM8: 857.14286 | BN8: 857.14286 | BO8: 857.14286 | BP8: 857.14286 | BQ8: 857.14286 | BR8: 857.14286 | BS8: 857.14286 | BT8: 857.14286 | BU8: 857.14286 | BV8: 857.14286 | BW8: 857.14286 | BX8: 857.14286 | BY8: 857.14286 | BZ8: 857.14286 | CA8: 857.14286 | CB8: 857.14286 | CC8: 857.14286 | CD8: 857.14286 | CE8: 857.14286 | CF8: 857.14286 | CG8: 857.14286 | CH8: 857.14286 | CI8: 857.14286 | CJ8: 857.14286 | CK8: 857.14286 | CL8: 857.14286 | CM8: 857.14286 | CN8: 857.14286 | CO8: 857.14286 | CP8: 857.14286 | CQ8: 857.14286 | CR8: 857.14286 | CS8: 857.14286 | CT8: 857.14286 | CU8: 857.14286 | CV8: 857.14286 | CW8: 857.14286 | CX8: 857.14286 | CY8: 857.14286 | CZ8: 857.14286 | DA8: 857.14286 | DB8: 857.14286 | DC8: 857.14286 | DD8: 857.14286 | DE8: 857.14286 | DF8: 857.14286 | DG8: 857.14286 | DH8: 857.14286 | DI8: 857.14286 | DJ8: 857.14286 | DK8: 857.14286 | DL8: 857.14286 | DM8: 857.14286 | DN8: 857.14286 | DO8: 857.14286 | DP8: 857.14286 | DQ8: 857.14286 | DR8: 857.14286 | DS8: 857.14286 | DT8: 857.14286 | DU8: 857.14286 | DV8: 857.14286 | DW8: 857.14286 | DX8: 857.14286 | DY8: 857.14286 | DZ8: 857.14286 | EA8: 857.14286 | EB8: 857.14286 | EC8: 857.14286 | ED8: 857.14286 | EE8: 857.14286 | EF8: 857.14286 | EG8: 857.14286 | EH8: 857.14286 | EI8: 857.14286 | EJ8: 857.14286 | EK8: 857.14286 | EL8: 857.14286 | EM8: 857.14286 | EN8: 857.14286 | EO8: 857.14286 | EP8: 857.14286 | EQ8: 857.14286 | ER8: 857.14286 | ES8: 857.14286 | ET8: 857.14286 | EU8: 857.14286 | EV8: 857.14286 | EW8: 857.14286 | EX8: 857.14286 | EY8: 857.14286 | EZ8: 857.14286 | FA8: 857.14286 | FB8: 857.14286 | FC8: 857.14286 | FD8: 857.14286 | FE8: 857.14286 | FF8: 857.14286 | FG8: 857.14286 | FH8: 857.14286 | FI8: 857.14286 | FJ8: 857.14286 | FK8: 857.14286 | FL8: 857.14286 | FM8: 857.14286 | FN8: 857.14286 | FO8: 857.14286 | FP8: 857.14286 | FQ8: 857.14286 | FR8: 857.14286 | FS8: 857.14286 | FT8: 857.14286 | FU8: 857.14286 | FV8: 857.14286 | FW8: 857.14286 | FX8: 857.14286 | FY8: 857.14286
A9: 7 | B9: 1028.5714 | C9: 1028.5714 | D9: 1028.5714 | E9: 1028.5714 | F9: 1028.5714 | G9: 1028.5714 | H9: 1028.5714 | I9: 1028.5714 | J9: 1028.5714 | K9: 1028.5714 | L9: 1028.5714 | M9: 1028.5714 | N9: 1028.5714 | O9: 1028.5714 | P9: 1028.5714 | Q9: 1028.5714 | R9: 1028.5714 | S9: 1028.5714 | T9: 1028.5714 | U9: 1028.5714 | V9: 1028.5714 | W9: 1028.5714 | X9: 1028.5714 | Y9: 1028.5714 | Z9: 1028.5714 | AA9: 1028.5714 | AB9: 1028.5714 | AC9: 1028.5714 | AD9: 1028.5714 | AE9: 1028.5714 | AF9: 1028.5714 | AG9: 1028.5714 | AH9: 1028.5714 | AI9: 1028.5714 | AJ9: 1028.5714 | AK9: 1028.5714 | AL9: 1028.5714 | AM9: 1028.5714 | AN9: 1028.5714 | AO9: 1028.5714 | AP9: 1028.5714 | AQ9: 1028.5714 | AR9: 1028.5714 | AS9: 1028.5714 | AT9: 1028.5714 | AU9: 1028.5714 | AV9: 1028.5714 | AW9: 1028.5714 | AX9: 1028.5714 | AY9: 1028.5714 | AZ9: 1028.5714 | BA9: 1028.5714 | BB9: 1028.5714 | BC9: 1028.5714 | BD9: 1028.5714 | BE9: 1028.5714 | BF9: 1028.5714 | BG9: 1028.5714 | BH9: 1028.5714 | BI9: 1028.5714 | BJ9: 1028.5714 | BK9: 1028.5714 | BL9: 1028.5714 | BM9: 1028.5714 | BN9: 1028.5714 | BO9: 1028.5714 | BP9: 1028.5714 | BQ9: 1028.5714 | BR9: 1028.5714 | BS9: 1028.5714 | BT9: 1028.5714 | BU9: 1028.5714 | BV9: 1028.5714 | BW9: 1028.5714 | BX9: 1028.5714 | BY9: 1028.5714 | BZ9: 1028.5714 | CA9: 1028.5714 | CB9: 1028.5714 | CC9: 1028.5714 | CD9: 1028.5714 | CE9: 1028.5714 | CF9: 1028.5714 | CG9: 1028.5714 | CH9: 1028.5714 | CI9: 1028.5714 | CJ9: 1028.5714 | CK9: 1028.5714 | CL9: 1028.5714 | CM9: 1028.5714 | CN9: 1028.5714 | CO9: 1028.5714 | CP9: 1028.5714 | CQ9: 1028.5714 | CR9: 1028.5714 | CS9: 1028.5714 | CT9: 1028.5714 | CU9: 1028.5714 | CV9: 1028.5714 | CW9: 1028.5714 | CX9: 1028.5714 | CY9: 1028.5714 | CZ9: 1028.5714 | DA9: 1028.5714 | DB9: 1028.5714 | DC9: 1028.5714 | DD9: 1028.5714 | DE9: 1028.5714 | DF9: 1028.5714 | DG9: 1028.5714 | DH9: 1028.5714 | DI9: 1028.5714 | DJ9: 1028.5714 | DK9: 1028.5714 | DL9: 1028.5714 | DM9: 1028.5714 | DN9: 1028.5714 | DO9: 1028.5714 | DP9: 1028.5714 | DQ9: 1028.5714 | DR9: 1028.5714 | DS9: 1028.5714 | DT9: 1028.5714 | DU9: 1028.5714 | DV9: 1028.5714 | DW9: 1028.5714 | DX9: 1028.5714 | DY9: 1028.5714 | DZ9: 1028.5714 | EA9: 1028.5714 | EB9: 1028.5714 | EC9: 1028.5714 | ED9: 1028.5714 | EE9: 1028.5714 | EF9: 1028.5714 | EG9: 1028.5714 | EH9: 1028.5714 | EI9: 1028.5714 | EJ9: 1028.5714 | EK9: 1028.5714 | EL9: 1028.5714 | EM9: 1028.5714 | EN9: 1028.5714 | EO9: 1028.5714 | EP9: 1028.5714 | EQ9: 1028.5714 | ER9: 1028.5714 | ES9: 1028.5714 | ET9: 1028.5714 | EU9: 1028.5714 | EV9: 1028.5714 | EW9: 1028.5714 | EX9: 1028.5714 | EY9: 1028.5714 | EZ9: 1028.5714 | FA9: 1028.5714 | FB9: 1028.5714 | FC9: 1028.5714 | FD9: 1028.5714 | FE9: 1028.5714 | FF9: 1028.5714 | FG9: 1028.5714 | FH9: 1028.5714 | FI9: 1028.5714 | FJ9: 1028.5714 | FK9: 1028.5714 | FL9: 1028.5714 | FM9: 1028.5714 | FN9: 1028.5714 | FO9: 1028.5714 | FP9: 1028.5714 | FQ9: 1028.5714 | FR9: 1028.5714 | FS9: 1028.5714 | FT9: 1028.5714 | FU9: 1028.5714 | FV9: 1028.5714 | FW9: 1028.5714 | FX9: 1028.5714 | FY9: 1028.5714
A10: 8 | B10: 1200 | C10: 1200 | D10: 1200 | E10: 1200 | F10: 1200 | G10: 1200 | H10: 1200 | I10: 1200 | J10: 1200 | K10: 1200 | L10: 1200 | M10: 1200 | N10: 1200 | O10: 1200 | P10: 1200 | Q10: 1200 | R10: 1200 | S10: 1200 | T10: 1200 | U10: 1200 | V10: 1200 | W10: 1200 | X10: 1200 | Y10: 1200 | Z10: 1200 | AA10: 1200 | AB10: 1200 | AC10: 1200 | AD10: 1200 | AE10: 1200 | AF10: 1200 | AG10: 1200 | AH10: 1200 | AI10: 1200 | AJ10: 1200 | AK10: 1200 | AL10: 1200 | AM10: 1200 | AN10: 1200 | AO10: 1200 | AP10: 1200 | AQ10: 1200 | AR10: 1200 | AS10: 1200 | AT10: 1200 | AU10: 1200 | AV10: 1200 | AW10: 1200 | AX10: 1200 | AY10: 1200 | AZ10: 1200 | BA10: 1200 | BB10: 1200 | BC10: 1200 | BD10: 1200 | BE10: 1200 | BF10: 1200 | BG10: 1200 | BH10: 1200 | BI10: 1200 | BJ10: 1200 | BK10: 1200 | BL10: 1200 | BM10: 1200 | BN10: 1200 | BO10: 1200 | BP10: 1200 | BQ10: 1200 | BR10: 1200 | BS10: 1200 | BT10: 1200 | BU10: 1200 | BV10: 1200 | BW10: 1200 | BX10: 1200 | BY10: 1200 | BZ10: 1200 | CA10: 1200 | CB10: 1200 | CC10: 1200 | CD10: 1200 | CE10: 1200 | CF10: 1200 | CG10: 1200 | CH10: 1200 | CI10: 1200 | CJ10: 1200 | CK10: 1200 | CL10: 1200 | CM10: 1200 | CN10: 1200 | CO10: 1200 | CP10: 1200 | CQ10: 1200 | CR10: 1200 | CS10: 1200 | CT10: 1200 | CU10: 1200 | CV10: 1200 | CW10: 1200 | CX10: 1200 | CY10: 1200 | CZ10: 1200 | DA10: 1200 | DB10: 1200 | DC10: 1200 | DD10: 1200 | DE10: 1200 | DF10: 1200 | DG10: 1200 | DH10: 1200 | DI10: 1200 | DJ10: 1200 | DK10: 1200 | DL10: 1200 | DM10: 1200 | DN10: 1200 | DO10: 1200 | DP10: 1200 | DQ10: 1200 | DR10: 1200 | DS10: 1200 | DT10: 1200 | DU10: 1200 | DV10: 1200 | DW10: 1200 | DX10: 1200 | DY10: 1200 | DZ10: 1200 | EA10: 1200 | EB10: 1200 | EC10: 1200 | ED10: 1200 | EE10: 1200 | EF10: 1200 | EG10: 1200 | EH10: 1200 | EI10: 1200 | EJ10: 1200 | EK10: 1200 | EL10: 1200 | EM10: 1200 | EN10: 1200 | EO10: 1200 | EP10: 1200 | EQ10: 1200 | ER10: 1200 | ES10: 1200 | ET10: 1200 | EU10: 1200 | EV10: 1200 | EW10: 1200 | EX10: 1200 | EY10: 1200 | EZ10: 1200 | FA10: 1200 | FB10: 1200 | FC10: 1200 | FD10: 1200 | FE10: 1200 | FF10: 1200 | FG10: 1200 | FH10: 1200 | FI10: 1200 | FJ10: 1200 | FK10: 1200 | FL10: 1200 | FM10: 1200 | FN10: 1200 | FO10: 1200 | FP10: 1200 | FQ10: 1200 | FR10: 1200 | FS10: 1200 | FT10: 1200 | FU10: 1200 | FV10: 1200 | FW10: 1200 | FX10: 1200 | FY10: 1200
A11: 9 | B11: 1371.4286 | C11: 1371.4286 | D11: 1371.4286 | E11: 1371.4286 | F11: 1371.4286 | G11: 1371.4286 | H11: 1371.4286 | I11: 1371.4286 | J11: 1371.4286 | K11: 1371.4286 | L11: 1371.4286 | M11: 1371.4286 | N11: 1371.4286 | O11: 1371.4286 | P11: 1371.4286 | Q11: 1371.4286 | R11: 1371.4286 | S11: 1371.4286 | T11: 1371.4286 | U11: 1371.4286 | V11: 1371.4286 | W11: 1371.4286 | X11: 1371.4286 | Y11: 1371.4286 | Z11: 1371.4286 | AA11: 1371.4286 | AB11: 1371.4286 | AC11: 1371.4286 | AD11: 1371.4286 | AE11: 1371.4286 | AF11: 1371.4286 | AG11: 1371.4286 | AH11: 1371.4286 | AI11: 1371.4286 | AJ11: 1371.4286 | AK11: 1371.4286 | AL11: 1371.4286 | AM11: 1371.4286 | AN11: 1371.4286 | AO11: 1371.4286 | AP11: 1371.4286 | AQ11: 1371.4286 | AR11: 1371.4286 | AS11: 1371.4286 | AT11: 1371.4286 | AU11: 1371.4286 | AV11: 1371.4286 | AW11: 1371.4286 | AX11: 1371.4286 | AY11: 1371.4286 | AZ11: 1371.4286 | BA11: 1371.4286 | BB11: 1371.4286 | BC11: 1371.4286 | BD11: 1371.4286 | BE11: 1371.4286 | BF11: 1371.4286 | BG11: 1371.4286 | BH11: 1371.4286 | BI11: 1371.4286 | BJ11: 1371.4286 | BK11: 1371.4286 | BL11: 1371.4286 | BM11: 1371.4286 | BN11: 1371.4286 | BO11: 1371.4286 | BP11: 1371.4286 | BQ11: 1371.4286 | BR11: 1371.4286 | BS11: 1371.4286 | BT11: 1371.4286 | BU11: 1371.4286 | BV11: 1371.4286 | BW11: 1371.4286 | BX11: 1371.4286 | BY11: 1371.4286 | BZ11: 1371.4286 | CA11: 1371.4286 | CB11: 1371.4286 | CC11: 1371.4286 | CD11: 1371.4286 | CE11: 1371.4286 | CF11: 1371.4286 | CG11: 1371.4286 | CH11: 1371.4286 | CI11: 1371.4286 | CJ11: 1371.4286 | CK11: 1371.4286 | CL11: 1371.4286 | CM11: 1371.4286 | CN11: 1371.4286 | CO11: 1371.4286 | CP11: 1371.4286 | CQ11: 1371.4286 | CR11: 1371.4286 | CS11: 1371.4286 | CT11: 1371.4286 | CU11: 1371.4286 | CV11: 1371.4286 | CW11: 1371.4286 | CX11: 1371.4286 | CY11: 1371.4286 | CZ11: 1371.4286 | DA11: 1371.4286 | DB11: 1371.4286 | DC11: 1371.4286 | DD11: 1371.4286 | DE11: 1371.4286 | DF11: 1371.4286 | DG11: 1371.4286 | DH11: 1371.4286 | DI11: 1371.4286 | DJ11: 1371.4286 | DK11: 1371.4286 | DL11: 1371.4286 | DM11: 1371.4286 | DN11: 1371.4286 | DO11: 1371.4286 | DP11: 1371.4286 | DQ11: 1371.4286 | DR11: 1371.4286 | DS11: 1371.4286 | DT11: 1371.4286 | DU11: 1371.4286 | DV11: 1371.4286 | DW11: 1371.4286 | DX11: 1371.4286 | DY11: 1371.4286 | DZ11: 1371.4286 | EA11: 1371.4286 | EB11: 1371.4286 | EC11: 1371.4286 | ED11: 1371.4286 | EE11: 1371.4286 | EF11: 1371.4286 | EG11: 1371.4286 | EH11: 1371.4286 | EI11: 1371.4286 | EJ11: 1371.4286 | EK11: 1371.4286 | EL11: 1371.4286 | EM11: 1371.4286 | EN11: 1371.4286 | EO11: 1371.4286 | EP11: 1371.4286 | EQ11: 1371.4286 | ER11: 1371.4286 | ES11: 1371.4286 | ET11: 1371.4286 | EU11: 1371.4286 | EV11: 1371.4286 | EW11: 1371.4286 | EX11: 1371.4286 | EY11: 1371.4286 | EZ11: 1371.4286 | FA11: 1371.4286 | FB11: 1371.4286 | FC11: 1371.4286 | FD11: 1371.4286 | FE11: 1371.4286 | FF11: 1371.4286 | FG11: 1371.4286 | FH11: 1371.4286 | FI11: 1371.4286 | FJ11: 1371.4286 | FK11: 1371.4286 | FL11: 1371.4286 | FM11: 1371.4286 | FN11: 1371.4286 | FO11: 1371.4286 | FP11: 1371.4286 | FQ11: 1371.4286 | FR11: 1371.4286 | FS11: 1371.4286 | FT11: 1371.4286 | FU11: 1371.4286 | FV11: 1371.4286 | FW11: 1371.4286 | FX11: 1371.4286 | FY11: 1371.4286
